<?xml version="1.0" ?>
<!-- =================================================================================== -->
<!-- |    This document was autogenerated by xacro from tita.urdf.xacro                | -->
<!-- |    EDITING THIS FILE BY HAND IS NOT RECOMMENDED                                 | -->
<!-- =================================================================================== -->
<robot name="airbot">
  <material name="black">
    <color rgba="0.19607843137254902 0.19607843137254902 0.19607843137254902 1.0"/>
  </material>
  <material name="blue">
    <color rgba="0.0 0.0 0.8 1.0"/>
  </material>
  <material name="green">
    <color rgba="0.0 0.8 0.0 1.0"/>
  </material>
  <material name="grey">
    <color rgba="0.2 0.2 0.2 1.0"/>
  </material>
  <material name="silver">
    <color rgba="0.9137254901960784 0.9137254901960784 0.8470588235294118 1.0"/>
  </material>
  <material name="orange">
    <color rgba="1.0 0.4235294117647059 0.0392156862745098 1.0"/>
  </material>
  <material name="brown">
    <color rgba="0.8705882352941177 0.8117647058823529 0.7647058823529411 1.0"/>
  </material>
  <material name="red">
    <color rgba="0.8 0.0 0.0 1.0"/>
  </material>
  <material name="white">
    <color rgba="1.0 1.0 1.0 1.0"/>
  </material>
  
  <!-- arm -->
  <link name="flange">
    <inertial>
      <origin rpy="0 0 0" xyz="0.007 0. 0."/>
      <mass value="0.0206"/>
      <!-- should calcullate the inertia later -->
      <inertia ixx="0.0" ixy="0.0" ixz="0.0" iyy="0.0" iyz="0.0" izz="0.0"/>
    </inertial>
    <visual>
      <origin rpy="0. -1.5707964 0. " xyz="0.0040002 0.0219004 -0.0221024"/>
      <geometry>
        <mesh filename="../meshes/arm/flange/visual/flange.obj" scale="1. 1. 1."/>
      </geometry>
    </visual>
    <collision>
      <origin rpy="0. -1.5707964 0. " xyz="0.0040002 0.0219004 -0.0221024"/>
      <geometry>
        <mesh filename="../meshes/arm/flange/collision/flange.obj" scale="1. 1. 1."/>
      </geometry>
    </collision>
  </link>
  <link name="arm_base_link">
    <inertial>
      <origin rpy="0 0 0" xyz="-0.013241649 -0.0014483907 0.037394006"/>
      <mass value="0.683"/>
      <inertia ixx="0.00056691" ixy="7.5556E-06" ixz="1.0335E-06" iyy="0.00068606" iyz="7.7985E-07" izz="0.0010143"/>
    </inertial>
    <visual>
      <origin rpy="0 0 0" xyz="0 0 0"/>
      <geometry>
        <mesh filename="../meshes/arm/airbot_play_v3_1/visual/base_link.STL"/>
      </geometry>
      <material name="">
        <color rgba="0.75294 0.75294 0.75294 1"/>
      </material>
    </visual>
    <collision>
      <origin rpy="0 0 0" xyz="0 0 0"/>
      <geometry>
        <mesh filename="../meshes/arm/airbot_play_v3_1/collision/base_link.STL"/>
      </geometry>
    </collision>
  </link>
  <link name="link1">
    <inertial>
      <origin rpy="0 0 0" xyz="5.6582251E-05 -0.0025468634 -0.026016066"/>
      <mass value="0.609"/>
      <inertia ixx="0.00026059" ixy="-2.1857E-07" ixz="1.3032E-06" iyy="0.00035988" iyz="1.5738E-05" izz="0.00030082"/>
    </inertial>
    <visual>
      <origin rpy="0 0 0" xyz="0 0 0"/>
      <geometry>
        <mesh filename="../meshes/arm/airbot_play_v3_1/visual/link1.STL"/>
      </geometry>
      <material name="">
        <color rgba="0.75294 0.75294 0.75294 1"/>
      </material>
    </visual>
    <!-- <collision>
      <origin rpy="0 0 0" xyz="0 0 0"/>
      <geometry>
        <mesh filename="../meshes/arm/airbot_play_v3_1/collision/link1.STL"/>
      </geometry>
    </collision> -->
  </link>
  <joint name="joint_arm_1" type="revolute">
    <origin rpy="0 0 0" xyz="0 0 0.1117"/>
    <parent link="arm_base_link"/>
    <child link="link1"/>
    <axis xyz="0 0 1"/>
    <!--limit effort="12" lower="-3.151" upper="2.089" velocity="8.2"/-->
    <limit effort="20" lower="-3.151" upper="2.089" velocity="2."/>
  </joint>
  <link name="link2">
    <inertial>
      <origin rpy="0 0 0" xyz="0.15031499 0.0071730548 0.0016032489"/>
      <mass value="0.902"/>
      <inertia ixx="0.00040289" ixy="-0.00012909" ixz="4.6597E-05" iyy="0.003174" iyz="9.7791E-06" izz="0.0033885"/>
    </inertial>
    <visual>
      <origin rpy="0 0 0" xyz="0 0 0"/>
      <geometry>
        <mesh filename="../meshes/arm/airbot_play_v3_1/visual/link2.STL"/>
      </geometry>
      <material name="">
        <color rgba="0.75294 0.75294 0.75294 1"/>
      </material>
    </visual>
    <!-- <collision>
      <origin rpy="0 0 0" xyz="0 0 0"/>
      <geometry>
        <mesh filename="../meshes/arm/airbot_play_v3_1/collision/link2.STL"/>
      </geometry>
    </collision> -->
  </link>
  <joint name="joint_arm_2" type="revolute">
    <origin rpy="-1.5691 -0.38673 3.1409" xyz="0 0 0"/>
    <parent link="link1"/>
    <child link="link2"/>
    <axis xyz="0 0 1"/>
    <!--limit effort="12" lower="-2.963" upper="0.181" velocity="6.28"/-->
    <limit effort="20" lower="-2.963" upper="0.181" velocity="2."/>
  </joint>
  <link name="link3">
    <inertial>
      <origin rpy="0 0 0" xyz="2.8745009E-05 0.11006382 0.0042664091"/>
      <mass value="0.683"/>
      <inertia ixx="0.0011117" ixy="2.9694E-07" ixz="-1.1205E-07" iyy="0.00022817" iyz="0.00014247" izz="0.0011062"/>
    </inertial>
    <visual>
      <origin rpy="0 0 0" xyz="0 0 0"/>
      <geometry>
        <mesh filename="../meshes/arm/airbot_play_v3_1/visual/link3.STL"/>
      </geometry>
      <material name="">
        <color rgba="0.75294 0.75294 0.75294 1"/>
      </material>
    </visual>
    <!-- <collision>
      <origin rpy="0 0 0" xyz="0 0 0"/>
      <geometry>
        <mesh filename="../meshes/arm/airbot_play_v3_1/collision/link3.STL"/>
      </geometry>
    </collision> -->
  </link>
  <joint name="joint_arm_3" type="revolute">
    <origin rpy="0 0.0015895 1.9575" xyz="0.27009 0 0"/>
    <parent link="link2"/>
    <child link="link3"/>
    <axis xyz="0 0 1"/>
    <!--limit effort="12" lower="-0.094" upper="3.161" velocity="6.28"/-->
    <limit effort="20" lower="-0.094" upper="3.161" velocity="6.8"/>
  </joint>
  <link name="link4">
    <inertial>
      <origin rpy="0 0 0" xyz="-4.3875215E-05 0.00050280749 -0.020529025"/>
      <mass value="0.358"/>
      <inertia ixx="0.00011024" ixy="6.4278E-09" ixz="-5.8907E-08" iyy="0.00013798" iyz="-7.8592E-06" izz="0.00011351"/>
    </inertial>
    <visual>
      <origin rpy="0 0 0" xyz="0 0 0"/>
      <geometry>
        <mesh filename="../meshes/arm/airbot_play_v3_1/visual/link4.STL"/>
      </geometry>
      <material name="">
        <color rgba="0.75294 0.75294 0.75294 1"/>
      </material>
    </visual>
    <!-- <collision>
      <origin rpy="0 0 0" xyz="0 0 0"/>
      <geometry>
        <mesh filename="../meshes/arm/airbot_play_v3_1/collision/link4.STL"/>
      </geometry>
    </collision> -->
  </link>
  <joint name="joint_arm_4" type="revolute">
    <origin rpy="-1.5708 -1.5708 0" xyz="8.2128E-05 0.29015 0"/>
    <parent link="link3"/>
    <child link="link4"/>
    <axis xyz="0 0 1"/>
    <!--limit effort="3" lower="-3.012" upper="3.012" velocity="6.28"/-->
    <limit effort="3" lower="-3.012" upper="3.012" velocity="6.8"/>
  </joint>
  <link name="link5">
    <inertial>
      <origin rpy="0 0 0" xyz="1.0725637E-04 0.037609585 0.00094283927"/>
      <mass value="0.403"/>
      <inertia ixx="0.00014324" ixy="-1.2363E-07" ixz="-1.6092E-07" iyy="0.00015285" iyz="1.3894E-05" izz="0.00014936"/>
    </inertial>
    <visual>
      <origin rpy="0 0 0" xyz="0 0 0"/>
      <geometry>
        <mesh filename="../meshes/arm/airbot_play_v3_1/visual/link5.STL"/>
      </geometry>
      <material name="">
        <color rgba="0.75294 0.75294 0.75294 1"/>
      </material>
    </visual>
    <!-- <collision>
      <origin rpy="0 0 0" xyz="0 0 0"/>
      <geometry>
        <mesh filename="../meshes/arm/airbot_play_v3_1/collision/link5.STL"/>
      </geometry>
    </collision> -->
  </link>
  <joint name="joint_arm_5" type="revolute">
    <origin rpy="1.5708 0 0" xyz="0 0 0"/>
    <parent link="link4"/>
    <child link="link5"/>
    <axis xyz="0 0 1"/>
    <!--limit effort="3" lower="-1.859" upper="1.859" velocity="6.28"/-->
    <limit effort="3" lower="-1.7" upper="1.7" velocity="6.8"/>
  </joint>
  <link name="link6">
    <inertial>
      <origin rpy="0 0 0" xyz="-0.022 0 0"/>
      <mass value="0.118"/>
      <inertia ixx="2.3175E-05" ixy="-8.0893E-10" ixz="-2.5166E-14" iyy="1.2978E-05" iyz="-2.9196E-09" izz="1.2976E-05"/>
    </inertial>
    <visual>
      <origin rpy="0 0 0" xyz="0 0 0"/>
      <geometry>
        <mesh filename="../meshes/arm/airbot_play_v3_1/visual/link6.STL"/>
      </geometry>
      <material name="">
        <color rgba="0.75294 0.75294 0.75294 1"/>
      </material>
    </visual>
    <!-- <collision>
      <origin rpy="0 0 0" xyz="0 0 0"/>
      <geometry>
        <mesh filename="../meshes/arm/airbot_play_v3_1/collision/link6.STL"/>
      </geometry>
    </collision> -->
  </link>
  <joint name="joint_arm_6" type="revolute">
    <origin rpy="0 0 1.5708" xyz="0 0.0864 0"/>
    <parent link="link5"/>
    <child link="link6"/>
    <axis xyz="1 0 0"/>
    <!--limit effort="3" lower="-3.017" upper="3.017" velocity="6.28"/-->
    <limit effort="3" lower="-3.017" upper="3.017" velocity="6.8"/>
  </joint>
  <joint name="arm_to_flange" type="fixed" dont_collapse="true">
    <origin rpy="0 0 0" xyz="0 0 0"/>
    <parent link="link6"/>
    <child link="flange"/>
  </joint>
  <!--link name="G2_base_link"-->
  <link name="link_G2_base">
    <inertial>
      <origin rpy="0 0 0" xyz="0.046303 -9.8611E-06 -1.4675E-05"/>
      <mass value="0.26507"/>
      <inertia ixx="348.3689417" ixy="0.2800965" ixz="-0.0560724" iyy="198.5351968" iyz="1.3076668" izz="449.2281738"/>
    </inertial>
    <visual>
      <origin rpy="0 0 0" xyz="0 0 0"/>
      <geometry>
        <mesh filename="../meshes/arm/G2/visual/base_link.STL"/>
      </geometry>
      <material name="">
        <color rgba="0.75294 0.75294 0.75294 1"/>
      </material>
    </visual>
    <collision>
      <origin rpy="0 0 0" xyz="0 0 0"/>
      <geometry>
        <mesh filename="../meshes/arm/G2/collision/base_link.STL"/>
      </geometry>
    </collision>
  </link>
  <link name="G2_link1">
    <inertial>
      <origin rpy="0 0 0" xyz="-0.015415 -0.066964 0.014312"/>
      <mass value="0.078003"/>
      <inertia ixx="34.1905834" ixy="-0.1388713" ixz="-0.4368816" iyy="54.1781125" iyz="6.8453757" izz="27.3518738"/>
    </inertial>
    <visual>
      <origin rpy="0 0 0" xyz="0 0 0"/>
      <geometry>
        <mesh filename="../meshes/arm/G2/visual/link1.STL"/>
      </geometry>
      <material name="">
        <color rgba="0.75294 0.75294 0.75294 1"/>
      </material>
    </visual>
    <collision>
      <origin rpy="0 0 0" xyz="0 0 0"/>
      <geometry>
        <mesh filename="../meshes/arm/G2/collision/link1.STL"/>
      </geometry>
    </collision>
  </link>
  <joint name="G2_joint1" type="fixed">
    <origin rpy="0 1.5708 0" xyz="0.0736 0.05 -0.015"/>
    <!--parent link="G2_base_link"/-->
    <parent link="link_G2_base"/>
    <child link="G2_link1"/>
    <axis xyz="0 1 0"/>
    <limit effort="3" lower="-0.034" upper="0" velocity="1"/>
    <mimic joint="gripper_joint" multiplier="-0.034" offset="0"/>
  </joint>
  <link name="G2_link2">
    <inertial>
      <origin rpy="0 0 0" xyz="-0.014585 0.066964 0.014312"/>
      <mass value="0.078003"/>
      <inertia ixx="34.1905834" ixy="-0.1388713" ixz="0.4368816" iyy="54.1781125" iyz="-6.8453757" izz="27.3518738"/>
    </inertial>
    <visual>
      <origin rpy="0 0 0" xyz="0 0 0"/>
      <geometry>
        <mesh filename="../meshes/arm/G2/visual/link2.STL"/>
      </geometry>
      <material name="">
        <color rgba="0.75294 0.75294 0.75294 1"/>
      </material>
    </visual>
    <collision>
      <origin rpy="0 0 0" xyz="0 0 0"/>
      <geometry>
        <mesh filename="../meshes/arm/G2/collision/link2.STL"/>
      </geometry>
    </collision>
  </link>
  <joint name="G2_joint2" type="fixed">
    <origin rpy="0 1.5708 0" xyz="0.0736 -0.05 -0.015"/>
    <!--parent link="G2_base_link"/-->
    <parent link="link_G2_base"/>
    <child link="G2_link2"/>
    <axis xyz="0 1 0"/>
    <limit effort="3" lower="0" upper="0.034" velocity="1"/>
    <mimic joint="gripper_joint" multiplier="0.034" offset="0"/>
  </joint>
  <joint name="gripper_joint" type="fixed">
    <origin rpy="0 0 0" xyz="0 0 0"/>
    <axis xyz="0 0 1"/>
    <!--parent link="G2_base_link"/-->
    <parent link="link_G2_base"/>
    <child link="rotate_motor"/>
    <limit effort="20" lower="0" upper="1" velocity="3.1415926"/>
  </joint>
  <link name="rotate_motor"/>
  <joint name="gripper_connector" type="fixed" dont_collapse="true">
    <origin rpy="0 0 0" xyz="0.009 0 0"/>
    <parent link="flange"/>
    <!--child link="G2_base_link"/-->
    <child link="link_G2_base"/>
  </joint>
  <link name="end_link">
    <inertial>
      <origin rpy="0 0 0" xyz="-0.104492 0 0"/>
      <mass value="0.605"/>
      <inertia ixx="0.0003483689417" ixy="0.0000002800965" ixz="-0.0000000560724" iyy="0.0070013022796" iyz="0.0000013076668" izz="0.007251995256600001"/>
    </inertial>
  </link>
  <joint name="end_joint" type="fixed">
    <origin rpy="0 0 0" xyz="0.1602 0 0"/>
    <parent link="flange"/>
    <child link="end_link"/>
  </joint>
</robot>
